DataLoader worker (pid(s) 7657) exited unexpectedlyTraceback (most recent call last):
  File "/home/baker/inverse-tracr/venv/lib/python3.10/site-packages/torch/utils/data/dataloader.py", line 1132, in _try_get_data
    data = self._data_queue.get(timeout=timeout)
  File "/usr/lib/python3.10/multiprocessing/queues.py", line 114, in get
    raise Empty
_queue.Empty

The above exception was the direct cause of the following exception:

Traceback (most recent call last):
  File "/home/baker/inverse-tracr/train_compressed_w_emb_multiproc.py", line 439, in <module>
    batch = next(it)
  File "/home/baker/inverse-tracr/venv/lib/python3.10/site-packages/torch/utils/data/dataloader.py", line 633, in __next__
    data = self._next_data()
  File "/home/baker/inverse-tracr/venv/lib/python3.10/site-packages/torch/utils/data/dataloader.py", line 1328, in _next_data
    idx, data = self._get_data()
  File "/home/baker/inverse-tracr/venv/lib/python3.10/site-packages/torch/utils/data/dataloader.py", line 1294, in _get_data
    success, data = self._try_get_data()
  File "/home/baker/inverse-tracr/venv/lib/python3.10/site-packages/torch/utils/data/dataloader.py", line 1145, in _try_get_data
    raise RuntimeError('DataLoader worker (pid(s) {}) exited unexpectedly'.format(pids_str)) from e
RuntimeError: DataLoader worker (pid(s) 7657) exited unexpectedly
